[2025-05-25T17:27:08.340+0000] {taskinstance.py:1125} INFO - Dependencies all met for dep_context=non-requeueable deps ti=<TaskInstance: data_pipeline.create_raw_schema scheduled__2025-05-01T00:00:00+00:00 [queued]>
[2025-05-25T17:27:08.354+0000] {taskinstance.py:1125} INFO - Dependencies all met for dep_context=requeueable deps ti=<TaskInstance: data_pipeline.create_raw_schema scheduled__2025-05-01T00:00:00+00:00 [queued]>
[2025-05-25T17:27:08.354+0000] {taskinstance.py:1331} INFO - Starting attempt 2 of 2
[2025-05-25T17:27:08.371+0000] {taskinstance.py:1350} INFO - Executing <Task(PostgresOperator): create_raw_schema> on 2025-05-01 00:00:00+00:00
[2025-05-25T17:27:08.385+0000] {standard_task_runner.py:57} INFO - Started process 694 to run task
[2025-05-25T17:27:08.392+0000] {standard_task_runner.py:84} INFO - Running: ['***', 'tasks', 'run', 'data_pipeline', 'create_raw_schema', 'scheduled__2025-05-01T00:00:00+00:00', '--job-id', '17', '--raw', '--subdir', 'DAGS_FOLDER/data_pipeline.py', '--cfg-path', '/tmp/tmp_r8lnwvb']
[2025-05-25T17:27:08.398+0000] {standard_task_runner.py:85} INFO - Job 17: Subtask create_raw_schema
[2025-05-25T17:27:08.498+0000] {task_command.py:410} INFO - Running <TaskInstance: data_pipeline.create_raw_schema scheduled__2025-05-01T00:00:00+00:00 [running]> on host bf217478d96c
[2025-05-25T17:27:08.625+0000] {taskinstance.py:1568} INFO - Exporting env vars: AIRFLOW_CTX_DAG_OWNER='***' AIRFLOW_CTX_DAG_ID='data_pipeline' AIRFLOW_CTX_TASK_ID='create_raw_schema' AIRFLOW_CTX_EXECUTION_DATE='2025-05-01T00:00:00+00:00' AIRFLOW_CTX_TRY_NUMBER='2' AIRFLOW_CTX_DAG_RUN_ID='scheduled__2025-05-01T00:00:00+00:00'
[2025-05-25T17:27:08.627+0000] {sql.py:262} INFO - Executing: CREATE SCHEMA IF NOT EXISTS raw_data;
[2025-05-25T17:27:08.663+0000] {taskinstance.py:1847} ERROR - Task failed with exception
Traceback (most recent call last):
  File "/home/airflow/.local/lib/python3.9/site-packages/airflow/providers/common/sql/operators/sql.py", line 263, in execute
    hook = self.get_db_hook()
  File "/home/airflow/.local/lib/python3.9/site-packages/airflow/providers/common/sql/operators/sql.py", line 181, in get_db_hook
    return self._hook
  File "/usr/local/lib/python3.9/functools.py", line 993, in __get__
    val = self.func(instance)
  File "/home/airflow/.local/lib/python3.9/site-packages/airflow/providers/common/sql/operators/sql.py", line 143, in _hook
    conn = BaseHook.get_connection(self.conn_id)
  File "/home/airflow/.local/lib/python3.9/site-packages/airflow/hooks/base.py", line 72, in get_connection
    conn = Connection.get_connection_from_secrets(conn_id)
  File "/home/airflow/.local/lib/python3.9/site-packages/airflow/models/connection.py", line 434, in get_connection_from_secrets
    raise AirflowNotFoundException(f"The conn_id `{conn_id}` isn't defined")
airflow.exceptions.AirflowNotFoundException: The conn_id `postgresql+psycopg2://***:***@mlops-postgres:5432/***` isn't defined
[2025-05-25T17:27:08.671+0000] {taskinstance.py:1368} INFO - Marking task as FAILED. dag_id=data_pipeline, task_id=create_raw_schema, execution_date=20250501T000000, start_date=20250525T172708, end_date=20250525T172708
[2025-05-25T17:27:08.687+0000] {standard_task_runner.py:104} ERROR - Failed to execute job 17 for task create_raw_schema (The conn_id `postgresql+psycopg2://***:***@mlops-postgres:5432/***` isn't defined; 694)
[2025-05-25T17:27:08.726+0000] {local_task_job_runner.py:232} INFO - Task exited with return code 1
[2025-05-25T17:27:08.788+0000] {taskinstance.py:2674} INFO - 0 downstream tasks scheduled from follow-on schedule check
