[2025-05-25T16:11:37.286+0000] {taskinstance.py:1125} INFO - Dependencies all met for dep_context=non-requeueable deps ti=<TaskInstance: raw_data_pipeline.create_raw_table scheduled__2025-05-01T00:00:00+00:00 [queued]>
[2025-05-25T16:11:37.303+0000] {taskinstance.py:1125} INFO - Dependencies all met for dep_context=requeueable deps ti=<TaskInstance: raw_data_pipeline.create_raw_table scheduled__2025-05-01T00:00:00+00:00 [queued]>
[2025-05-25T16:11:37.303+0000] {taskinstance.py:1331} INFO - Starting attempt 2 of 2
[2025-05-25T16:11:37.323+0000] {taskinstance.py:1350} INFO - Executing <Task(PythonOperator): create_raw_table> on 2025-05-01 00:00:00+00:00
[2025-05-25T16:11:37.335+0000] {standard_task_runner.py:57} INFO - Started process 8070 to run task
[2025-05-25T16:11:37.344+0000] {standard_task_runner.py:84} INFO - Running: ['***', 'tasks', 'run', 'raw_data_pipeline', 'create_raw_table', 'scheduled__2025-05-01T00:00:00+00:00', '--job-id', '4', '--raw', '--subdir', 'DAGS_FOLDER/data_pipeline.py', '--cfg-path', '/tmp/tmpnm7h6t7f']
[2025-05-25T16:11:37.350+0000] {standard_task_runner.py:85} INFO - Job 4: Subtask create_raw_table
[2025-05-25T16:11:37.460+0000] {task_command.py:410} INFO - Running <TaskInstance: raw_data_pipeline.create_raw_table scheduled__2025-05-01T00:00:00+00:00 [running]> on host 56418040e25f
[2025-05-25T16:11:37.611+0000] {taskinstance.py:1568} INFO - Exporting env vars: AIRFLOW_CTX_DAG_OWNER='***' AIRFLOW_CTX_DAG_ID='raw_data_pipeline' AIRFLOW_CTX_TASK_ID='create_raw_table' AIRFLOW_CTX_EXECUTION_DATE='2025-05-01T00:00:00+00:00' AIRFLOW_CTX_TRY_NUMBER='2' AIRFLOW_CTX_DAG_RUN_ID='scheduled__2025-05-01T00:00:00+00:00'
[2025-05-25T16:11:37.625+0000] {taskinstance.py:1847} ERROR - Task failed with exception
Traceback (most recent call last):
  File "/home/airflow/.local/lib/python3.9/site-packages/sqlalchemy/engine/base.py", line 3361, in _wrap_pool_connect
    return fn()
  File "/home/airflow/.local/lib/python3.9/site-packages/sqlalchemy/pool/base.py", line 327, in connect
    return _ConnectionFairy._checkout(self)
  File "/home/airflow/.local/lib/python3.9/site-packages/sqlalchemy/pool/base.py", line 894, in _checkout
    fairy = _ConnectionRecord.checkout(pool)
  File "/home/airflow/.local/lib/python3.9/site-packages/sqlalchemy/pool/base.py", line 493, in checkout
    rec = pool._do_get()
  File "/home/airflow/.local/lib/python3.9/site-packages/sqlalchemy/pool/impl.py", line 146, in _do_get
    self._dec_overflow()
  File "/home/airflow/.local/lib/python3.9/site-packages/sqlalchemy/util/langhelpers.py", line 70, in __exit__
    compat.raise_(
  File "/home/airflow/.local/lib/python3.9/site-packages/sqlalchemy/util/compat.py", line 211, in raise_
    raise exception
  File "/home/airflow/.local/lib/python3.9/site-packages/sqlalchemy/pool/impl.py", line 143, in _do_get
    return self._create_connection()
  File "/home/airflow/.local/lib/python3.9/site-packages/sqlalchemy/pool/base.py", line 273, in _create_connection
    return _ConnectionRecord(self)
  File "/home/airflow/.local/lib/python3.9/site-packages/sqlalchemy/pool/base.py", line 388, in __init__
    self.__connect()
  File "/home/airflow/.local/lib/python3.9/site-packages/sqlalchemy/pool/base.py", line 691, in __connect
    pool.logger.debug("Error on connect(): %s", e)
  File "/home/airflow/.local/lib/python3.9/site-packages/sqlalchemy/util/langhelpers.py", line 70, in __exit__
    compat.raise_(
  File "/home/airflow/.local/lib/python3.9/site-packages/sqlalchemy/util/compat.py", line 211, in raise_
    raise exception
  File "/home/airflow/.local/lib/python3.9/site-packages/sqlalchemy/pool/base.py", line 686, in __connect
    self.dbapi_connection = connection = pool._invoke_creator(self)
  File "/home/airflow/.local/lib/python3.9/site-packages/sqlalchemy/engine/create.py", line 574, in connect
    return dialect.connect(*cargs, **cparams)
  File "/home/airflow/.local/lib/python3.9/site-packages/sqlalchemy/engine/default.py", line 598, in connect
    return self.dbapi.connect(*cargs, **cparams)
  File "/home/airflow/.local/lib/python3.9/site-packages/psycopg2/__init__.py", line 122, in connect
    conn = _connect(dsn, connection_factory=connection_factory, **kwasync)
psycopg2.OperationalError: connection to server at "mlops-postgres" (172.18.0.2), port 5432 failed: FATAL:  database "raw_data" does not exist


The above exception was the direct cause of the following exception:

Traceback (most recent call last):
  File "/home/airflow/.local/lib/python3.9/site-packages/airflow/operators/python.py", line 181, in execute
    return_value = self.execute_callable()
  File "/home/airflow/.local/lib/python3.9/site-packages/airflow/operators/python.py", line 198, in execute_callable
    return self.python_callable(*self.op_args, **self.op_kwargs)
  File "/opt/airflow/dags/data_pipeline.py", line 73, in create_raw_table
    with engine.begin() as conn:
  File "/home/airflow/.local/lib/python3.9/site-packages/sqlalchemy/engine/base.py", line 3143, in begin
    conn = self.connect(close_with_result=close_with_result)
  File "/home/airflow/.local/lib/python3.9/site-packages/sqlalchemy/engine/base.py", line 3315, in connect
    return self._connection_cls(self, close_with_result=close_with_result)
  File "/home/airflow/.local/lib/python3.9/site-packages/sqlalchemy/engine/base.py", line 96, in __init__
    else engine.raw_connection()
  File "/home/airflow/.local/lib/python3.9/site-packages/sqlalchemy/engine/base.py", line 3394, in raw_connection
    return self._wrap_pool_connect(self.pool.connect, _connection)
  File "/home/airflow/.local/lib/python3.9/site-packages/sqlalchemy/engine/base.py", line 3364, in _wrap_pool_connect
    Connection._handle_dbapi_exception_noconnection(
  File "/home/airflow/.local/lib/python3.9/site-packages/sqlalchemy/engine/base.py", line 2198, in _handle_dbapi_exception_noconnection
    util.raise_(
  File "/home/airflow/.local/lib/python3.9/site-packages/sqlalchemy/util/compat.py", line 211, in raise_
    raise exception
  File "/home/airflow/.local/lib/python3.9/site-packages/sqlalchemy/engine/base.py", line 3361, in _wrap_pool_connect
    return fn()
  File "/home/airflow/.local/lib/python3.9/site-packages/sqlalchemy/pool/base.py", line 327, in connect
    return _ConnectionFairy._checkout(self)
  File "/home/airflow/.local/lib/python3.9/site-packages/sqlalchemy/pool/base.py", line 894, in _checkout
    fairy = _ConnectionRecord.checkout(pool)
  File "/home/airflow/.local/lib/python3.9/site-packages/sqlalchemy/pool/base.py", line 493, in checkout
    rec = pool._do_get()
  File "/home/airflow/.local/lib/python3.9/site-packages/sqlalchemy/pool/impl.py", line 146, in _do_get
    self._dec_overflow()
  File "/home/airflow/.local/lib/python3.9/site-packages/sqlalchemy/util/langhelpers.py", line 70, in __exit__
    compat.raise_(
  File "/home/airflow/.local/lib/python3.9/site-packages/sqlalchemy/util/compat.py", line 211, in raise_
    raise exception
  File "/home/airflow/.local/lib/python3.9/site-packages/sqlalchemy/pool/impl.py", line 143, in _do_get
    return self._create_connection()
  File "/home/airflow/.local/lib/python3.9/site-packages/sqlalchemy/pool/base.py", line 273, in _create_connection
    return _ConnectionRecord(self)
  File "/home/airflow/.local/lib/python3.9/site-packages/sqlalchemy/pool/base.py", line 388, in __init__
    self.__connect()
  File "/home/airflow/.local/lib/python3.9/site-packages/sqlalchemy/pool/base.py", line 691, in __connect
    pool.logger.debug("Error on connect(): %s", e)
  File "/home/airflow/.local/lib/python3.9/site-packages/sqlalchemy/util/langhelpers.py", line 70, in __exit__
    compat.raise_(
  File "/home/airflow/.local/lib/python3.9/site-packages/sqlalchemy/util/compat.py", line 211, in raise_
    raise exception
  File "/home/airflow/.local/lib/python3.9/site-packages/sqlalchemy/pool/base.py", line 686, in __connect
    self.dbapi_connection = connection = pool._invoke_creator(self)
  File "/home/airflow/.local/lib/python3.9/site-packages/sqlalchemy/engine/create.py", line 574, in connect
    return dialect.connect(*cargs, **cparams)
  File "/home/airflow/.local/lib/python3.9/site-packages/sqlalchemy/engine/default.py", line 598, in connect
    return self.dbapi.connect(*cargs, **cparams)
  File "/home/airflow/.local/lib/python3.9/site-packages/psycopg2/__init__.py", line 122, in connect
    conn = _connect(dsn, connection_factory=connection_factory, **kwasync)
sqlalchemy.exc.OperationalError: (psycopg2.OperationalError) connection to server at "mlops-postgres" (172.18.0.2), port 5432 failed: FATAL:  database "raw_data" does not exist

(Background on this error at: https://sqlalche.me/e/14/e3q8)
[2025-05-25T16:11:37.656+0000] {taskinstance.py:1368} INFO - Marking task as FAILED. dag_id=raw_data_pipeline, task_id=create_raw_table, execution_date=20250501T000000, start_date=20250525T161137, end_date=20250525T161137
[2025-05-25T16:11:37.679+0000] {standard_task_runner.py:104} ERROR - Failed to execute job 4 for task create_raw_table ((psycopg2.OperationalError) connection to server at "mlops-postgres" (172.18.0.2), port 5432 failed: FATAL:  database "raw_data" does not exist

(Background on this error at: https://sqlalche.me/e/14/e3q8); 8070)
[2025-05-25T16:11:37.716+0000] {local_task_job_runner.py:232} INFO - Task exited with return code 1
[2025-05-25T16:11:37.779+0000] {taskinstance.py:2674} INFO - 0 downstream tasks scheduled from follow-on schedule check
[2025-05-25T16:47:03.540+0000] {taskinstance.py:1125} INFO - Dependencies all met for dep_context=non-requeueable deps ti=<TaskInstance: raw_data_pipeline.create_raw_table scheduled__2025-05-01T00:00:00+00:00 [queued]>
[2025-05-25T16:47:03.557+0000] {taskinstance.py:1125} INFO - Dependencies all met for dep_context=requeueable deps ti=<TaskInstance: raw_data_pipeline.create_raw_table scheduled__2025-05-01T00:00:00+00:00 [queued]>
[2025-05-25T16:47:03.558+0000] {taskinstance.py:1331} INFO - Starting attempt 2 of 2
[2025-05-25T16:47:03.580+0000] {taskinstance.py:1350} INFO - Executing <Task(PythonOperator): create_raw_table> on 2025-05-01 00:00:00+00:00
[2025-05-25T16:47:03.592+0000] {standard_task_runner.py:57} INFO - Started process 147 to run task
[2025-05-25T16:47:03.603+0000] {standard_task_runner.py:84} INFO - Running: ['***', 'tasks', 'run', 'raw_data_pipeline', 'create_raw_table', 'scheduled__2025-05-01T00:00:00+00:00', '--job-id', '4', '--raw', '--subdir', 'DAGS_FOLDER/data_pipeline.py', '--cfg-path', '/tmp/tmps7mz99wg']
[2025-05-25T16:47:03.608+0000] {standard_task_runner.py:85} INFO - Job 4: Subtask create_raw_table
[2025-05-25T16:47:03.692+0000] {task_command.py:410} INFO - Running <TaskInstance: raw_data_pipeline.create_raw_table scheduled__2025-05-01T00:00:00+00:00 [running]> on host bf217478d96c
[2025-05-25T16:47:03.828+0000] {taskinstance.py:1568} INFO - Exporting env vars: AIRFLOW_CTX_DAG_OWNER='***' AIRFLOW_CTX_DAG_ID='raw_data_pipeline' AIRFLOW_CTX_TASK_ID='create_raw_table' AIRFLOW_CTX_EXECUTION_DATE='2025-05-01T00:00:00+00:00' AIRFLOW_CTX_TRY_NUMBER='2' AIRFLOW_CTX_DAG_RUN_ID='scheduled__2025-05-01T00:00:00+00:00'
[2025-05-25T16:47:03.855+0000] {taskinstance.py:1847} ERROR - Task failed with exception
Traceback (most recent call last):
  File "/home/airflow/.local/lib/python3.9/site-packages/airflow/operators/python.py", line 181, in execute
    return_value = self.execute_callable()
  File "/home/airflow/.local/lib/python3.9/site-packages/airflow/operators/python.py", line 198, in execute_callable
    return self.python_callable(*self.op_args, **self.op_kwargs)
  File "/opt/airflow/dags/data_pipeline.py", line 41, in create_raw_table
    CREATE TABLE IF NOT EXISTS {SCHEMA}.{TABLE} (
NameError: name 'TABLE' is not defined
[2025-05-25T16:47:03.873+0000] {taskinstance.py:1368} INFO - Marking task as FAILED. dag_id=raw_data_pipeline, task_id=create_raw_table, execution_date=20250501T000000, start_date=20250525T164703, end_date=20250525T164703
[2025-05-25T16:47:03.889+0000] {standard_task_runner.py:104} ERROR - Failed to execute job 4 for task create_raw_table (name 'TABLE' is not defined; 147)
[2025-05-25T16:47:03.931+0000] {local_task_job_runner.py:232} INFO - Task exited with return code 1
[2025-05-25T16:47:03.982+0000] {taskinstance.py:2674} INFO - 0 downstream tasks scheduled from follow-on schedule check
