[2025-05-25T16:57:28.763+0000] {taskinstance.py:1125} INFO - Dependencies all met for dep_context=non-requeueable deps ti=<TaskInstance: raw_data_pipeline.load_raw_batch scheduled__2025-05-01T00:00:00+00:00 [queued]>
[2025-05-25T16:57:28.794+0000] {taskinstance.py:1125} INFO - Dependencies all met for dep_context=requeueable deps ti=<TaskInstance: raw_data_pipeline.load_raw_batch scheduled__2025-05-01T00:00:00+00:00 [queued]>
[2025-05-25T16:57:28.794+0000] {taskinstance.py:1331} INFO - Starting attempt 2 of 2
[2025-05-25T16:57:28.829+0000] {taskinstance.py:1350} INFO - Executing <Task(PythonOperator): load_raw_batch> on 2025-05-01 00:00:00+00:00
[2025-05-25T16:57:28.846+0000] {standard_task_runner.py:57} INFO - Started process 294 to run task
[2025-05-25T16:57:28.858+0000] {standard_task_runner.py:84} INFO - Running: ['***', 'tasks', 'run', 'raw_data_pipeline', 'load_raw_batch', 'scheduled__2025-05-01T00:00:00+00:00', '--job-id', '9', '--raw', '--subdir', 'DAGS_FOLDER/data_pipeline.py', '--cfg-path', '/tmp/tmpxsqjucgq']
[2025-05-25T16:57:28.864+0000] {standard_task_runner.py:85} INFO - Job 9: Subtask load_raw_batch
[2025-05-25T16:57:28.963+0000] {task_command.py:410} INFO - Running <TaskInstance: raw_data_pipeline.load_raw_batch scheduled__2025-05-01T00:00:00+00:00 [running]> on host bf217478d96c
[2025-05-25T16:57:29.135+0000] {taskinstance.py:1568} INFO - Exporting env vars: AIRFLOW_CTX_DAG_OWNER='***' AIRFLOW_CTX_DAG_ID='raw_data_pipeline' AIRFLOW_CTX_TASK_ID='load_raw_batch' AIRFLOW_CTX_EXECUTION_DATE='2025-05-01T00:00:00+00:00' AIRFLOW_CTX_TRY_NUMBER='2' AIRFLOW_CTX_DAG_RUN_ID='scheduled__2025-05-01T00:00:00+00:00'
[2025-05-25T16:57:57.520+0000] {warnings.py:109} WARNING - /opt/***/dags/data_pipeline.py:88: UserWarning: pandas only supports SQLAlchemy connectable (engine/connection) or database string URI or sqlite3 DBAPI2 connection. Other DBAPI2 objects are not tested. Please consider using SQLAlchemy.
  cur = conn.cursor()

[2025-05-25T16:57:57.601+0000] {taskinstance.py:1847} ERROR - Task failed with exception
Traceback (most recent call last):
  File "/home/airflow/.local/lib/python3.9/site-packages/pandas/io/sql.py", line 2674, in execute
    cur.execute(sql, *args)
psycopg2.errors.UndefinedTable: relation "sqlite_master" does not exist
LINE 5:             sqlite_master
                    ^


The above exception was the direct cause of the following exception:

Traceback (most recent call last):
  File "/home/airflow/.local/lib/python3.9/site-packages/airflow/operators/python.py", line 181, in execute
    return_value = self.execute_callable()
  File "/home/airflow/.local/lib/python3.9/site-packages/airflow/operators/python.py", line 198, in execute_callable
    return self.python_callable(*self.op_args, **self.op_kwargs)
  File "/opt/airflow/dags/data_pipeline.py", line 88, in load_raw_batch
    cur = conn.cursor()
  File "/home/airflow/.local/lib/python3.9/site-packages/pandas/util/_decorators.py", line 333, in wrapper
    return func(*args, **kwargs)
  File "/home/airflow/.local/lib/python3.9/site-packages/pandas/core/generic.py", line 3087, in to_sql
    return sql.to_sql(
  File "/home/airflow/.local/lib/python3.9/site-packages/pandas/io/sql.py", line 842, in to_sql
    return pandas_sql.to_sql(
  File "/home/airflow/.local/lib/python3.9/site-packages/pandas/io/sql.py", line 2850, in to_sql
    table.create()
  File "/home/airflow/.local/lib/python3.9/site-packages/pandas/io/sql.py", line 984, in create
    if self.exists():
  File "/home/airflow/.local/lib/python3.9/site-packages/pandas/io/sql.py", line 970, in exists
    return self.pd_sql.has_table(self.name, self.schema)
  File "/home/airflow/.local/lib/python3.9/site-packages/pandas/io/sql.py", line 2865, in has_table
    return len(self.execute(query, [name]).fetchall()) > 0
  File "/home/airflow/.local/lib/python3.9/site-packages/pandas/io/sql.py", line 2686, in execute
    raise ex from exc
pandas.errors.DatabaseError: Execution failed on sql '
        SELECT
            name
        FROM
            sqlite_master
        WHERE
            type IN ('table', 'view')
            AND name=?;
        ': relation "sqlite_master" does not exist
LINE 5:             sqlite_master
                    ^

[2025-05-25T16:57:57.627+0000] {taskinstance.py:1368} INFO - Marking task as FAILED. dag_id=raw_data_pipeline, task_id=load_raw_batch, execution_date=20250501T000000, start_date=20250525T165728, end_date=20250525T165757
[2025-05-25T16:57:57.650+0000] {standard_task_runner.py:104} ERROR - Failed to execute job 9 for task load_raw_batch (Execution failed on sql '
        SELECT
            name
        FROM
            sqlite_master
        WHERE
            type IN ('table', 'view')
            AND name=?;
        ': relation "sqlite_master" does not exist
LINE 5:             sqlite_master
                    ^
; 294)
[2025-05-25T16:57:57.726+0000] {local_task_job_runner.py:232} INFO - Task exited with return code 1
[2025-05-25T16:57:57.762+0000] {taskinstance.py:2674} INFO - 0 downstream tasks scheduled from follow-on schedule check
[2025-05-25T17:07:49.876+0000] {taskinstance.py:1125} INFO - Dependencies all met for dep_context=non-requeueable deps ti=<TaskInstance: raw_data_pipeline.load_raw_batch scheduled__2025-05-01T00:00:00+00:00 [queued]>
[2025-05-25T17:07:49.895+0000] {taskinstance.py:1125} INFO - Dependencies all met for dep_context=requeueable deps ti=<TaskInstance: raw_data_pipeline.load_raw_batch scheduled__2025-05-01T00:00:00+00:00 [queued]>
[2025-05-25T17:07:49.895+0000] {taskinstance.py:1331} INFO - Starting attempt 2 of 2
[2025-05-25T17:07:49.915+0000] {taskinstance.py:1350} INFO - Executing <Task(PythonOperator): load_raw_batch> on 2025-05-01 00:00:00+00:00
[2025-05-25T17:07:49.925+0000] {standard_task_runner.py:57} INFO - Started process 441 to run task
[2025-05-25T17:07:49.935+0000] {standard_task_runner.py:84} INFO - Running: ['***', 'tasks', 'run', 'raw_data_pipeline', 'load_raw_batch', 'scheduled__2025-05-01T00:00:00+00:00', '--job-id', '14', '--raw', '--subdir', 'DAGS_FOLDER/data_pipeline.py', '--cfg-path', '/tmp/tmpnikeqewb']
[2025-05-25T17:07:49.939+0000] {standard_task_runner.py:85} INFO - Job 14: Subtask load_raw_batch
[2025-05-25T17:07:50.029+0000] {task_command.py:410} INFO - Running <TaskInstance: raw_data_pipeline.load_raw_batch scheduled__2025-05-01T00:00:00+00:00 [running]> on host bf217478d96c
[2025-05-25T17:07:50.184+0000] {taskinstance.py:1568} INFO - Exporting env vars: AIRFLOW_CTX_DAG_OWNER='***' AIRFLOW_CTX_DAG_ID='raw_data_pipeline' AIRFLOW_CTX_TASK_ID='load_raw_batch' AIRFLOW_CTX_EXECUTION_DATE='2025-05-01T00:00:00+00:00' AIRFLOW_CTX_TRY_NUMBER='2' AIRFLOW_CTX_DAG_RUN_ID='scheduled__2025-05-01T00:00:00+00:00'
[2025-05-25T17:07:50.188+0000] {taskinstance.py:1847} ERROR - Task failed with exception
Traceback (most recent call last):
  File "/home/airflow/.local/lib/python3.9/site-packages/airflow/operators/python.py", line 181, in execute
    return_value = self.execute_callable()
  File "/home/airflow/.local/lib/python3.9/site-packages/airflow/operators/python.py", line 198, in execute_callable
    return self.python_callable(*self.op_args, **self.op_kwargs)
  File "/opt/airflow/dags/data_pipeline.py", line 71, in load_raw_batch
    resp = requests.get(API_URL)
  File "/home/airflow/.local/lib/python3.9/site-packages/requests/api.py", line 73, in get
    return request("get", url, params=params, **kwargs)
  File "/home/airflow/.local/lib/python3.9/site-packages/requests/api.py", line 59, in request
    return session.request(method=method, url=url, **kwargs)
  File "/home/airflow/.local/lib/python3.9/site-packages/requests/sessions.py", line 573, in request
    prep = self.prepare_request(req)
  File "/home/airflow/.local/lib/python3.9/site-packages/requests/sessions.py", line 484, in prepare_request
    p.prepare(
  File "/home/airflow/.local/lib/python3.9/site-packages/requests/models.py", line 368, in prepare
    self.prepare_url(url, params)
  File "/home/airflow/.local/lib/python3.9/site-packages/requests/models.py", line 439, in prepare_url
    raise MissingSchema(
requests.exceptions.MissingSchema: Invalid URL 'None': No scheme supplied. Perhaps you meant https://None?
[2025-05-25T17:07:50.213+0000] {taskinstance.py:1368} INFO - Marking task as FAILED. dag_id=raw_data_pipeline, task_id=load_raw_batch, execution_date=20250501T000000, start_date=20250525T170749, end_date=20250525T170750
[2025-05-25T17:07:50.234+0000] {standard_task_runner.py:104} ERROR - Failed to execute job 14 for task load_raw_batch (Invalid URL 'None': No scheme supplied. Perhaps you meant https://None?; 441)
[2025-05-25T17:07:50.262+0000] {local_task_job_runner.py:232} INFO - Task exited with return code 1
[2025-05-25T17:07:50.300+0000] {taskinstance.py:2674} INFO - 0 downstream tasks scheduled from follow-on schedule check
